Workbook

Sheet Introduction
B1: Extracting data for the *.trj files with the trajectories of the main wells in FORGE (author: d.karvounis@geo-energie.ch, b.dyer@geo-energie.ch)
B3: Here, all wellhead locations are collected. These locations are read from the file "FORGE Pads and Seismic Locations.csv", the values of which are pasted in the current sheet.
B4: Trajectories are collected for wells: 16A-32, 56-32, 58-32, and 78A/B-32. Each trajectrory is in the respective Sheet.
B5: Stimulation will happen at well 16A-32 and geophones or FO will be deployed along the rest of the wells. A local cartesian coordinate system is considered that is centered around the wellhead of 16A-32.
B6: For making the trj files, only the first four columns are required from each Sheet. These columns are always automatically shifted from the values in cells [B:22:43] and are always in US ft
B7: The depth reference for the trajectory files is GL at 16A
B8: 16A data from FORGE directional surveysCompiled.xls based on FORGE directional surveys.xls from PW 17/12/21. This file also contains the same data as the raw data file sources listed below
B9: Drilling Summary Well 16A(78)-32 is the EOWR for 16A and contains the casing details
B11: Note: | C11: An inconsistency seems to exist with regards to the true position of 16A-32, between files "FORGE Pads and Seismic Locations.csv" and the well's survey in 16A(78)-32 Survey.xslx". Here I only consider locations from "FORGE Pads and Seismic Locations.csv". Cells [A:E,16:19] assess this error
B13: Files Read per trajectory: | K13: Personal communication between Clay Jones and Ben Dyer (13.12.2021)
B14: Wellhead locations | C14: 16A-32 | D14: 56-32 | E14: 58-32 | F14: 78A-32 | G14: 78B-32
B15: FORGE Pads and Seismic Locations.csv | C15: FORGE directional surveys.xls | D15: 56-32 EOWR - Final 22 July 2021.pdf | E15: DirectionalSurveyRpt_171027103004.pdf | F15: EOWR_78-32_profile.pdf | G15: FORGE directional surveys.xlsx (Sheet for 78B-32) | K15: Well | L15: Kelly Bushing (feet above ground level)
B17: Phil Wannamaker, 17 December 2021 | H17: Phil Wannamaker, 17 December 2021 | K17: 58-32 | L17: 21.5
K18: 68-32 | L18: 5.7
C19: Easting (X) [m] | D19: Northing (Y)[m] | E19: Latitude | F19: Longitude | G19: Elevation | H19: Elevation | K19: 78-32 | L19: 5.7
B20: Zero reference Point (0, 0, 0) (16A-32 Well) | C20: =C39 -> 334641.19 | D20: =D39 -> 4263443.7 | E20: =E39 -> 38.504021 | F20: =F39 -> -112.89639 | G20: =F39 -> -112.89639 | H20: =G39 -> 1650.0249 | K20: 16A(78)-32 | L20: 30.4
C21: Easting (X) [usft] | D21: Northing (Y) [usft] | E21: Latitude | F21: Longitude | G21: Elevation | H21: Elevation | K21: 56-32 | L21: 30.4
B22: Zero reference Point (0, 0, 0) (16A-32 Well) | C22: =C20/0.3048 -> 1097904.2 | D22: =D20/0.3048 -> 13987676 | E22: =E39 -> 38.504021 | F22: =F39 -> -112.89639 | G22: =G20/0.3048 -> -370.39498 | H22: =H20/0.3048 -> 5413.4675 | K22: 78B-32 | L22: 30.4
B26: Reference Point and wellhead position for 16A-32 | C26: Location of 16A-32 in | D26: =C39 -> 334641.19 | E26: =D39 -> 4263443.7 | F26: =G39 -> 1650.0249
B27: X_start, 1,097,896.92 usft | C27: =1097896.92*0.3048 -> 334638.98 | D27: =D26-C27 -> 2.207884 | E27: =E26-C28 -> 9.43604 | F27: =F26-C29*0.3048 -> -0.000756
B28: Y_start, 13,987,645.20 usft | C28: =13987645.2*0.3048 -> 4263434.3 | D28: Files "FORGE Pads and Seismic Locations.csv" and "16A(78)-32 Survey.xslx" have a disagreement of (2.2, 9.4, 0.2) meters in each direction
B29: Z_start, 5,414 usft | C29: 5413.47
E31: FORGE Pads and Seismic Locations.csv
B32: UTM Zone:12 North, Datum Trans:NAD 1983 (Conus) (Molodensky), Global Ref Datum:WGS 1984, Global Ref Epoch:2005, Geoid Model:GEOID18 (Conus)
B34: Point ID | C34: Easting (X) | D34: Northing (Y) | E34: Latitude | F34: Longitude | G34: Elevation | H34: Feature Code | I34: Notes
B35: 16A-32-NEC | C35: 334713.23 | D35: 4263489.4 | E35: 38.504446 | F35: -112.89557 | G35: 1650.0901 | H35: WELL-PAD | I35: Measured on pad
B36: 16A-32-NWC | C36: 334596.4 | D36: 4263569 | E36: 38.505142 | F36: -112.89693 | G36: 1648.8839 | H36: WELL-PAD | I36: Measured on pad
B37: 16A-32-SEC | C37: 334687.54 | D37: 4263380.7 | E37: 38.503462 | F37: -112.89584 | G37: 1649.8054 | H37: WELL-PAD | I37: Measured on pad
B38: 16A-32-SWC | C38: 334556.63 | D38: 4263416.5 | E38: 38.503761 | F38: -112.89735 | G38: 1649.1617 | H38: WELL-PAD | I38: Measured on pad
B39: 16A-32-WELL | C39: 334641.19 | D39: 4263443.7 | E39: 38.504021 | F39: -112.89639 | G39: 1650.0249 | H39: WELL
B40: 56-32-NEC | C40: 335557.22 | D40: 4263459.2 | E40: 38.504331 | F40: -112.88589 | G40: 1661.6002 | H40: WELL_PAD | I40: Measured on pad (Updated)
B41: 56-32-NWC | C41: 335457.44 | D41: 4263462.4 | E41: 38.504341 | F41: -112.88704 | G41: 1661.4867 | H41: WELL_PAD | I41: Measured on pad
B42: 56-32-SEC | C42: 335548.66 | D42: 4263405.4 | E42: 38.503844 | F42: -112.88598 | G42: 1656.5237 | H42: WELL_PAD | I42: Measured on pad, poor precisions, bad reception, high error due to embankment (Updated)
B43: 56-32-SWC | C43: 335456.34 | D43: 4263398.4 | E43: 38.503765 | F43: -112.88704 | G43: 1661.795 | H43: WELL_PAD | I43: Measured on pad
B44: 56-32-WELL | C44: 335504.28 | D44: 4263426.2 | E44: 38.504024 | F44: -112.88649 | G44: 1661.652 | H44: WELL
B45: 58-32-NEC | C45: 335512.4 | D45: 4263071 | E45: 38.500825 | F45: -112.88632 | G45: 1685.2112 | H45: WELL-PAD | I45: Measured on pad
B46: 58-32-NWC | C46: 335366.1 | D46: 4263068.5 | E46: 38.500776 | F46: -112.88799 | G46: 1684.8863 | H46: WELL-PAD | I46: Measured on pad
B47: 58-32-SEC | C47: 335512.68 | D47: 4262997.5 | E47: 38.500164 | F47: -112.8863 | G47: 1684.9264 | H47: WELL-PAD | I47: Measured on pad
B48: 58-32-SWC | C48: 335361.59 | D48: 4263003 | E48: 38.500185 | F48: -112.88803 | G48: 1684.6068 | H48: WELL-PAD | I48: Measured on pad
B49: 58-32-WELL | C49: 335450.99 | D49: 4263037.9 | E49: 38.500516 | F49: -112.88701 | G49: 1684.7724 | H49: WELL
...

Sheet Trajectory78B-32
F1: FORGE directional surveys.xlsx | L1: File Processed | O1: Sender | P1: Date received
B2: X | C2: Y | D2: Z | F2: E-W (ft) | G2: N-S (ft) | H2: TVD (ft) | L2: =Introduction!G15 -> FORGE directional surveys.xlsx (Sheet for 78B-32) | O2: =Introduction!H17 -> Phil Wannamaker, 17 December 2021
A3: 1 | B3: =F3+$L$10 -> 4016.604 | C3: =G3+M$10 -> -1509.7244 | D3: =H3-P$10 - Q$9 -> -212.78615 | F3: 0 | G3: 0 | H3: 0 | L3: Clay Jones 3/2/22 FORGE wellhead flanges wrt GL.docx
A4: 2 | B4: =F4+$L$10 -> 4016.604 | C4: =G4+M$10 -> -1508.2244 | D4: =H4-P$10 - Q$9 -> 28.213845 | F4: 0 | G4: 1.5 | H4: 241 | L4: Easting (X) [m] | M4: Northing (Y ) [m] | N4: Latitude | O4: Longitude | P4: Elevation [m] | Q4: Kelly Bushing [m] | R4: Flange
A5: =IF(F5,1+A4,"") -> 3 | B5: =F5+$L$10 -> 4016.504 | C5: =G5+M$10 -> -1506.8244 | D5: =H5-P$10 - Q$9 -> 124.21385 | F5: -0.1 | G5: 2.9 | H5: 337 | K5: Well's actual location | L5: =Introduction!C64 -> 335865.45 | M5: =Introduction!D64 -> 4262983.5 | N5: =Introduction!E64 -> 38.500103 | O5: =Introduction!F64 -> -112.88225 | P5: =Introduction!G64 -> 1705.6162 | Q5: =Q9*0.3048 -> 9.26592
A6: =IF(F6,1+A5,"") -> 4 | B6: =F6+$L$10 -> 4016.804 | C6: =G6+M$10 -> -1504.9244 | D6: =H6-P$10 - Q$9 -> 332.21385 | F6: 0.2 | G6: 4.8 | H6: 545 | K6: Wellhead wrt 16A | L6: =L5-Introduction!C39 -> 1224.2609 | M6: =M5-Introduction!D39 -> -460.164 | P6: =P5-Introduction!H20 -> 55.5913
A7: =IF(F7,1+A6,"") -> 5 | B7: =F7+$L$10 -> 4017.004 | C7: =G7+M$10 -> -1504.9244 | D7: =H7-P$10 - Q$9 -> 518.21385 | F7: 0.4 | G7: 4.8 | H7: 731
A8: =IF(F8,1+A7,"") -> 6 | B8: =F8+$L$10 -> 4017.004 | C8: =G8+M$10 -> -1504.9244 | D8: =H8-P$10 - Q$9 -> 609.21385 | F8: 0.4 | G8: 4.8 | H8: 822 | L8: Easting (X) [usft] | M8: Northing (Y ) [usft] | N8: Latitude | O8: Longitude | P8: Elevation [usft] | Q8: Kelly Bushing [ft]
A9: =IF(F9,1+A8,"") -> 7 | B9: =F9+$L$10 -> 4017.004 | C9: =G9+M$10 -> -1504.7244 | D9: =H9-P$10 - Q$9 -> 701.21385 | F9: 0.4 | G9: 5 | H9: 914 | K9: Well's actual location | L9: =L5/0.3048 -> 1101920.8 | M9: =M5/0.3048 -> 13986166 | N9: =N5 -> 38.500103 | O9: =O5 -> -112.88225 | P9: =P5/0.3048 -> 5595.8537 | Q9: =Introduction!L22 -> 30.4 | R9: 87.5"
A10: =IF(F10,1+A9,"") -> 8 | B10: =F10+$L$10 -> 4016.904 | C10: =G10+M$10 -> -1504.9244 | D10: =H10-P$10 - Q$9 -> 792.21385 | F10: 0.3 | G10: 4.8 | H10: 1005 | K10: Wellhead wrt 16A | L10: =L6/0.3048 -> 4016.604 | M10: =M6/0.3048 -> -1509.7244 | P10: =P6/0.3048 -> 182.38615
A11: =IF(F11,1+A10,"") -> 9 | B11: =F11+$L$10 -> 4016.904 | C11: =G11+M$10 -> -1505.2244 | D11: =H11-P$10 - Q$9 -> 888.21385 | F11: 0.3 | G11: 4.5 | H11: 1101
A12: =IF(F12,1+A11,"") -> 10 | B12: =F12+$L$10 -> 4016.804 | C12: =G12+M$10 -> -1505.0244 | D12: =H12-P$10 - Q$9 -> 982.21385 | F12: 0.2 | G12: 4.7 | H12: 1195
A13: =IF(F13,1+A12,"") -> 11 | B13: =F13+$L$10 -> 4016.904 | C13: =G13+M$10 -> -1504.9244 | D13: =H13-P$10 - Q$9 -> 1078.2138 | F13: 0.3 | G13: 4.8 | H13: 1291
A14: =IF(F14,1+A13,"") -> 12 | B14: =F14+$L$10 -> 4016.904 | C14: =G14+M$10 -> -1504.9244 | D14: =H14-P$10 - Q$9 -> 1173.2138 | F14: 0.3 | G14: 4.8 | H14: 1386 | K14: BD. Note there is no depth reference. DK assumes it is GL but it is usually KB
A15: =IF(F15,1+A14,"") -> 13 | B15: =F15+$L$10 -> 4017.004 | C15: =G15+M$10 -> -1505.0244 | D15: =H15-P$10 - Q$9 -> 1267.2138 | F15: 0.4 | G15: 4.7 | H15: 1480 | K15: Revised Z TVD to be Survey - Elevation - KB
A16: =IF(F16,1+A15,"") -> 14 | B16: =F16+$L$10 -> 4017.204 | C16: =G16+M$10 -> -1505.1244 | D16: =H16-P$10 - Q$9 -> 1363.2138 | F16: 0.6 | G16: 4.6 | H16: 1576 | K16: Trajectory depth reference | M16: KB | N16: =Q9 -> 30.4 | O16: ft above GL
A17: =IF(F17,1+A16,"") -> 15 | B17: =F17+$L$10 -> 4017.304 | C17: =G17+M$10 -> -1505.0244 | D17: =H17-P$10 - Q$9 -> 1457.2138 | F17: 0.7 | G17: 4.7 | H17: 1670
A18: =IF(F18,1+A17,"") -> 16 | B18: =F18+$L$10 -> 4017.104 | C18: =G18+M$10 -> -1505.2244 | D18: =H18-P$10 - Q$9 -> 1552.2138 | F18: 0.5 | G18: 4.5 | H18: 1765
A19: =IF(F19,1+A18,"") -> 17 | B19: =F19+$L$10 -> 4017.204 | C19: =G19+M$10 -> -1505.3244 | D19: =H19-P$10 - Q$9 -> 1648.2138 | F19: 0.6 | G19: 4.4 | H19: 1861
A20: =IF(F20,1+A19,"") -> 18 | B20: =F20+$L$10 -> 4017.204 | C20: =G20+M$10 -> -1505.4244 | D20: =H20-P$10 - Q$9 -> 1742.2138 | F20: 0.6 | G20: 4.3 | H20: 1955
A21: =IF(F21,1+A20,"") -> 19 | B21: =F21+$L$10 -> 4017.004 | C21: =G21+M$10 -> -1505.5244 | D21: =H21-P$10 - Q$9 -> 1837.2138 | F21: 0.4 | G21: 4.2 | H21: 2050
A22: =IF(F22,1+A21,"") -> 20 | B22: =F22+$L$10 -> 4016.804 | C22: =G22+M$10 -> -1505.6244 | D22: =H22-P$10 - Q$9 -> 1932.2138 | F22: 0.2 | G22: 4.1 | H22: 2145
A23: =IF(F23,1+A22,"") -> 21 | B23: =F23+$L$10 -> 4016.804 | C23: =G23+M$10 -> -1505.5244 | D23: =H23-P$10 - Q$9 -> 2027.2138 | F23: 0.2 | G23: 4.2 | H23: 2240
A24: =IF(F24,1+A23,"") -> 22 | B24: =F24+$L$10 -> 4017.104 | C24: =G24+M$10 -> -1505.6244 | D24: =H24-P$10 - Q$9 -> 2122.2138 | F24: 0.5 | G24: 4.1 | H24: 2335
A25: =IF(F25,1+A24,"") -> 23 | B25: =F25+$L$10 -> 4017.204 | C25: =G25+M$10 -> -1505.5244 | D25: =H25-P$10 - Q$9 -> 2218.2138 | F25: 0.6 | G25: 4.2 | H25: 2431
A26: =IF(F26,1+A25,"") -> 24 | B26: =F26+$L$10 -> 4017.304 | C26: =G26+M$10 -> -1505.5244 | D26: =H26-P$10 - Q$9 -> 2313.2138 | F26: 0.7 | G26: 4.2 | H26: 2526
A27: =IF(F27,1+A26,"") -> 25 | B27: =F27+$L$10 -> 4017.304 | C27: =G27+M$10 -> -1505.5244 | D27: =H27-P$10 - Q$9 -> 2407.2138 | F27: 0.7 | G27: 4.2 | H27: 2620
A28: =IF(F28,1+A27,"") -> 26 | B28: =F28+$L$10 -> 4017.404 | C28: =G28+M$10 -> -1505.6244 | D28: =H28-P$10 - Q$9 -> 2502.2138 | F28: 0.8 | G28: 4.1 | H28: 2715
... A102: =IF(F102,1+A101,"") -> 100 | B102: =F102+$L$10 -> 3945.804 | C102: =G102+M$10 -> -1542.8244 | D102: =H102-P$10 - Q$9 -> 9284.5138 | F102: -70.8 | G102: -33.1 | H102: 9497.3

Sheet Trajectory78A-32
A1: 78A-32 does NOT have a survey and is assumed to be vertical | K1: File Processed | N1: Sender | O1: Date received
F2: E-W (ft) | G2: N-S (ft) | H2: TVD (ft) | K2: EOWR_78-32_profile.pdf
A3: 1 | B3: =F3+$K$10 -> 3739.0128 | C3: =G3+L$10 -> -1481.9619 | D3: =H3-O$10 -> -170.25755 | F3: 0 | G3: 0 | H3: 0 | K3: Clay Jones 3/2/22 FORGE wellhead flanges wrt GL.docx
A4: 2 | B4: =F4+$K$10 -> 3739.0128 | C4: =G4+L$10 -> -1481.9619 | D4: =H4-O$10 -> -70.257546 | F4: 0 | G4: 0 | H4: 100 | K4: Easting (X) [m] | L4: Northing (Y ) [m] | M4: Latitude | N4: Longitude | O4: Elevation [m] | P4: Kelly Bushing [m] | Q4: Flange
A5: 3 | B5: =F5+$K$10 -> 3739.0128 | C5: =G5+L$10 -> -1481.9619 | D5: =H5-O$10 -> 29.742454 | F5: 0 | G5: 0 | H5: 200 | J5: Well's actual location | K5: =Introduction!C63 -> 335780.84 | L5: =Introduction!D63 -> 4262992 | M5: =Introduction!E63 -> 38.500164 | N5: =Introduction!F63 -> -112.88322 | O5: =Introduction!G63 -> 1701.9194 | P5: =P9*0.3048 -> 1.73736
A6: 4 | B6: =F6+$K$10 -> 3739.0128 | C6: =G6+L$10 -> -1481.9619 | D6: =H6-O$10 -> 129.74245 | F6: 0 | G6: 0 | H6: 300 | J6: Wellhead wrt 16A | K6: =K5-Introduction!C39 -> 1139.6511 | L6: =L5-Introduction!D39 -> -451.702 | O6: =O5-Introduction!H20 -> 51.8945
A7: 5 | B7: =F7+$K$10 -> 3739.0128 | C7: =G7+L$10 -> -1481.9619 | D7: =H7-O$10 -> 229.74245 | F7: 0 | G7: 0 | H7: 400
A8: 6 | B8: =F8+$K$10 -> 3739.0128 | C8: =G8+L$10 -> -1481.9619 | D8: =H8-O$10 -> 329.74245 | F8: 0 | G8: 0 | H8: 500 | K8: Easting (X) [usft] | L8: Northing (Y ) [usft] | M8: Latitude | N8: Longitude | O8: Elevation [usft] | P8: Kelly Bushing [ft]
A9: 7 | B9: =F9+$K$10 -> 3739.0128 | C9: =G9+L$10 -> -1481.9619 | D9: =H9-O$10 -> 429.74245 | F9: 0 | G9: 0 | H9: 600 | J9: Well's actual location | K9: =K5/0.3048 -> 1101643.2 | L9: =L5/0.3048 -> 13986194 | M9: =M5 -> 38.500164 | N9: =N5 -> -112.88322 | O9: =O5/0.3048 -> 5583.7251 | P9: 5.7 | Q9: 24.5
A10: 8 | B10: =F10+$K$10 -> 3739.0128 | C10: =G10+L$10 -> -1481.9619 | D10: =H10-O$10 -> 529.74245 | F10: 0 | G10: 0 | H10: 700 | J10: Wellhead wrt 16A | K10: =K6/0.3048 -> 3739.0128 | L10: =L6/0.3048 -> -1481.9619 | O10: =O6/0.3048 -> 170.25755
A11: 9 | B11: =F11+$K$10 -> 3739.0128 | C11: =G11+L$10 -> -1481.9619 | D11: =H11-O$10 -> 629.74245 | F11: 0 | G11: 0 | H11: 800
A12: 10 | B12: =F12+$K$10 -> 3739.0128 | C12: =G12+L$10 -> -1481.9619 | D12: =H12-O$10 -> 729.74245 | F12: 0 | G12: 0 | H12: 900
A13: 11 | B13: =F13+$K$10 -> 3739.0128 | C13: =G13+L$10 -> -1481.9619 | D13: =H13-O$10 -> 829.74245 | F13: 0 | G13: 0 | H13: 1000 | J13: Trajectory depth reference | L13: GL at 78A-32 | M13: =P6 -> 0 | N13: ft above GL
A14: 12 | B14: =F14+$K$10 -> 3739.0128 | C14: =G14+L$10 -> -1481.9619 | D14: =H14-O$10 -> 929.74245 | F14: 0 | G14: 0 | H14: 1100
A15: 13 | B15: =F15+$K$10 -> 3739.0128 | C15: =G15+L$10 -> -1481.9619 | D15: =H15-O$10 -> 1029.7425 | F15: 0 | G15: 0 | H15: 1200
A16: 14 | B16: =F16+$K$10 -> 3739.0128 | C16: =G16+L$10 -> -1481.9619 | D16: =H16-O$10 -> 1129.7425 | F16: 0 | G16: 0 | H16: 1300
A17: 15 | B17: =F17+$K$10 -> 3739.0128 | C17: =G17+L$10 -> -1481.9619 | D17: =H17-O$10 -> 1229.7425 | F17: 0 | G17: 0 | H17: 1400
A18: 16 | B18: =F18+$K$10 -> 3739.0128 | C18: =G18+L$10 -> -1481.9619 | D18: =H18-O$10 -> 1329.7425 | F18: 0 | G18: 0 | H18: 1500
A19: 17 | B19: =F19+$K$10 -> 3739.0128 | C19: =G19+L$10 -> -1481.9619 | D19: =H19-O$10 -> 1429.7425 | F19: 0 | G19: 0 | H19: 1600
A20: 18 | B20: =F20+$K$10 -> 3739.0128 | C20: =G20+L$10 -> -1481.9619 | D20: =H20-O$10 -> 1529.7425 | F20: 0 | G20: 0 | H20: 1700
A21: 19 | B21: =F21+$K$10 -> 3739.0128 | C21: =G21+L$10 -> -1481.9619 | D21: =H21-O$10 -> 1629.7425 | F21: 0 | G21: 0 | H21: 1800
A22: 20 | B22: =F22+$K$10 -> 3739.0128 | C22: =G22+L$10 -> -1481.9619 | D22: =H22-O$10 -> 1729.7425 | F22: 0 | G22: 0 | H22: 1900
A23: 21 | B23: =F23+$K$10 -> 3739.0128 | C23: =G23+L$10 -> -1481.9619 | D23: =H23-O$10 -> 1829.7425 | F23: 0 | G23: 0 | H23: 2000
A24: 22 | B24: =F24+$K$10 -> 3739.0128 | C24: =G24+L$10 -> -1481.9619 | D24: =H24-O$10 -> 1929.7425 | F24: 0 | G24: 0 | H24: 2100
A25: 23 | B25: =F25+$K$10 -> 3739.0128 | C25: =G25+L$10 -> -1481.9619 | D25: =H25-O$10 -> 2029.7425 | F25: 0 | G25: 0 | H25: 2200
... A36: 34 | B36: =F36+$K$10 -> 3739.0128 | C36: =G36+L$10 -> -1481.9619 | D36: =H36-O$10 -> 3109.7425 | F36: 0 | G36: 0 | H36: 3280

Sheet Trajectory56-32
A1: index | B1: X | C1: Y | D1: Z TVD | F1: Uncorrected X | G1: Uncorrected Y | H1: Uncorrected Z
A2: 1 | B2: =F2+K$14 -> 2831.6588 | C2: =G2+L$14 -> -57.427822 | D2: =H2-O$14 -> -38.146654 | F2: 0 | G2: 0 | H2: 0
A3: =A2+1 -> 2 | B3: =F3+K$14 -> 2831.9588 | C3: =G3+L$14 -> -57.227822 | D3: =H3-O$14 -> 162.85335 | F3: 0.3 | G3: 0.2 | H3: 201
A4: =A3+1 -> 3 | B4: =F4+K$14 -> 2832.3588 | C4: =G4+L$14 -> -56.927822 | D4: =H4-O$14 -> 253.85335 | F4: 0.7 | G4: 0.5 | H4: 292
A5: =A4+1 -> 4 | B5: =F5+K$14 -> 2833.0588 | C5: =G5+L$14 -> -56.127822 | D5: =H5-O$14 -> 362.85335 | F5: 1.4 | G5: 1.3 | H5: 401 | K5: File Processed | N5: Sender
A6: =A5+1 -> 5 | B6: =F6+K$14 -> 2833.2588 | C6: =G6+L$14 -> -55.027822 | D6: =H6-O$14 -> 454.85335 | F6: 1.6 | G6: 2.4 | H6: 493 | K6: =Introduction!D15 -> 56-32 EOWR - Final 22 July 2021.pdf | N6: =Introduction!E17 -> 0
A7: =A6+1 -> 6 | B7: =F7+K$14 -> 2833.1588 | C7: =G7+L$14 -> -53.527822 | D7: =H7-O$14 -> 546.85335 | F7: 1.5 | G7: 3.9 | H7: 585 | K7: Clay Jones 3/2/22 FORGE wellhead flanges wrt GL.docx
A8: =A7+1 -> 7 | B8: =F8+K$14 -> 2832.2588 | C8: =G8+L$14 -> -52.827822 | D8: =H8-O$14 -> 637.85335 | F8: 0.6 | G8: 4.6 | H8: 676 | K8: Easting (X) [m] | L8: Northing (Y ) [m] | M8: Latitude | N8: Longitude | O8: Elevation [m] | P8: Kelly Bushing [m] | Q8: Flange
A9: =A8+1 -> 8 | B9: =F9+K$14 -> 2831.3588 | C9: =G9+L$14 -> -51.927822 | D9: =H9-O$14 -> 728.85335 | F9: -0.3 | G9: 5.5 | H9: 767 | J9: Well's actual location | K9: =Introduction!C44 -> 335504.28 | L9: =Introduction!D44 -> 4263426.2 | M9: =Introduction!E44 -> 38.504024 | N9: =Introduction!F44 -> -112.88649 | O9: =Introduction!G44 -> 1661.652 | P9: =P13*0.3048 -> 9.26592
A10: =A9+1 -> 9 | B10: =F10+K$14 -> 2831.4588 | C10: =G10+L$14 -> -49.627822 | D10: =H10-O$14 -> 819.75335 | F10: -0.2 | G10: 7.8 | H10: 857.9 | J10: Wellhead wrt 16A | K10: =K9-Introduction!C20 -> 863.0896 | L10: =L9-Introduction!D20 -> -17.504 | O10: =O9-Introduction!H20 -> 11.6271
A11: =A10+1 -> 10 | B11: =F11+K$14 -> 2831.7588 | C11: =G11+L$14 -> -47.327822 | D11: =H11-O$14 -> 910.75335 | F11: 0.1 | G11: 10.1 | H11: 948.9
A12: =A11+1 -> 11 | B12: =F12+K$14 -> 2832.0588 | C12: =G12+L$14 -> -45.027822 | D12: =H12-O$14 -> 1001.7533 | F12: 0.4 | G12: 12.4 | H12: 1039.9 | K12: Easting (X) [usft] | L12: Northing (Y ) [usft] | M12: Latitude | N12: Longitude | O12: Elevation [usft] | P12: Kelly Bushing [ft]
A13: =A12+1 -> 12 | B13: =F13+K$14 -> 2832.4588 | C13: =G13+L$14 -> -42.327822 | D13: =H13-O$14 -> 1096.6533 | F13: 0.8 | G13: 15.1 | H13: 1134.8 | J13: Well's actual location | K13: =K9/0.3048 -> 1100735.8 | L13: =L9/0.3048 -> 13987619 | M13: =M9 -> 38.504024 | N13: =N9 -> -112.88649 | O13: =O9/0.3048 -> 5451.6142 | P13: =Introduction!L21 -> 30.4 | Q13: 57"
A14: =A13+1 -> 13 | B14: =F14+K$14 -> 2832.9588 | C14: =G14+L$14 -> -39.427822 | D14: =H14-O$14 -> 1191.6533 | F14: 1.3 | G14: 18 | H14: 1229.8 | J14: Wellhead wrt 16A | K14: =K10/0.3048 -> 2831.6588 | L14: =L10/0.3048 -> -57.427822 | O14: =O10/0.3048 -> 38.146654
A15: =A14+1 -> 14 | B15: =F15+K$14 -> 2833.7588 | C15: =G15+L$14 -> -36.427822 | D15: =H15-O$14 -> 1286.5533 | F15: 2.1 | G15: 21 | H15: 1324.7
A16: =A15+1 -> 15 | B16: =F16+K$14 -> 2834.6588 | C16: =G16+L$14 -> -33.427822 | D16: =H16-O$14 -> 1380.5533 | F16: 3 | G16: 24 | H16: 1418.7 | J16: According to 56-32 EOWR the depth reference is the surface for the survey data in column G here. Also same as depth reference in FORGE directional surveys.xlsx
A17: =A16+1 -> 16 | B17: =F17+K$14 -> 2835.7588 | C17: =G17+L$14 -> -30.827822 | D17: =H17-O$14 -> 1475.4533 | F17: 4.1 | G17: 26.6 | H17: 1513.6 | J17: Revised Z TVD to be Survey - Elevation
A18: =A17+1 -> 17 | B18: =F18+K$14 -> 2837.0588 | C18: =G18+L$14 -> -28.927822 | D18: =H18-O$14 -> 1569.4533 | F18: 5.4 | G18: 28.5 | H18: 1607.6
A19: =A18+1 -> 18 | B19: =F19+K$14 -> 2838.7588 | C19: =G19+L$14 -> -26.827822 | D19: =H19-O$14 -> 1664.4533 | F19: 7.1 | G19: 30.6 | H19: 1702.6 | J19: Trajectory depth reference | L19: GL | M19: 0 | N19: ft above GL
A20: =A19+1 -> 19 | B20: =F20+K$14 -> 2841.0588 | C20: =G20+L$14 -> -24.727822 | D20: =H20-O$14 -> 1759.3533 | F20: 9.4 | G20: 32.7 | H20: 1797.5
A21: =A20+1 -> 20 | B21: =F21+K$14 -> 2843.1588 | C21: =G21+L$14 -> -23.027822 | D21: =H21-O$14 -> 1853.3533 | F21: 11.5 | G21: 34.4 | H21: 1891.5
A22: =A21+1 -> 21 | B22: =F22+K$14 -> 2845.0588 | C22: =G22+L$14 -> -22.127822 | D22: =H22-O$14 -> 1947.3533 | F22: 13.4 | G22: 35.3 | H22: 1985.5
A23: =A22+1 -> 22 | B23: =F23+K$14 -> 2847.1588 | C23: =G23+L$14 -> -21.227822 | D23: =H23-O$14 -> 2042.2533 | F23: 15.5 | G23: 36.2 | H23: 2080.4
A24: =A23+1 -> 23 | B24: =F24+K$14 -> 2849.1588 | C24: =G24+L$14 -> -20.427822 | D24: =H24-O$14 -> 2136.2533 | F24: 17.5 | G24: 37 | H24: 2174.4
A25: =A24+1 -> 24 | B25: =F25+K$14 -> 2851.2588 | C25: =G25+L$14 -> -19.527822 | D25: =H25-O$14 -> 2231.2533 | F25: 19.6 | G25: 37.9 | H25: 2269.4
A26: =A25+1 -> 25 | B26: =F26+K$14 -> 2853.3588 | C26: =G26+L$14 -> -18.527822 | D26: =H26-O$14 -> 2326.1533 | F26: 21.7 | G26: 38.9 | H26: 2364.3
A27: =A26+1 -> 26 | B27: =F27+K$14 -> 2855.4588 | C27: =G27+L$14 -> -17.927822 | D27: =H27-O$14 -> 2419.1533 | F27: 23.8 | G27: 39.5 | H27: 2457.3
A28: =A27+1 -> 27 | B28: =F28+K$14 -> 2857.7588 | C28: =G28+L$14 -> -17.227822 | D28: =H28-O$14 -> 2512.1533 | F28: 26.1 | G28: 40.2 | H28: 2550.3
A29: =A28+1 -> 28 | B29: =F29+K$14 -> 2860.8588 | C29: =G29+L$14 -> -16.527822 | D29: =H29-O$14 -> 2609.0533 | F29: 29.2 | G29: 40.9 | H29: 2647.2
A30: =A29+1 -> 29 | B30: =F30+K$14 -> 2864.1588 | C30: =G30+L$14 -> -16.027822 | D30: =H30-O$14 -> 2704.0533 | F30: 32.5 | G30: 41.4 | H30: 2742.2
A31: =A30+1 -> 30 | B31: =F31+K$14 -> 2867.0588 | C31: =G31+L$14 -> -15.427822 | D31: =H31-O$14 -> 2799.9533 | F31: 35.4 | G31: 42 | H31: 2838.1
... A98: =A97+1 -> 97 | B98: =F98+K$14 -> 2725.2588 | C98: =G98+L$14 -> -76.927822 | D98: =H98-O$14 -> 9100.1533 | F98: -106.4 | G98: -19.5 | H98: 9138.3

Sheet Trajectory16A-32
G1: Data from FORGE directional surveysCompiled.xls based on FORGE directional surveys.xls from PW 17/12/21
B3: X | C3: Y | D3: Z TVD | E3: MD rKB | G3: X | H3: Y | I3: TVD | J3: MD
A4: 1 | B4: =G4 -> 0 | C4: =H4 -> 0 | D4: =I4-R$12 -> -30.4 | E4: =J4 -> 0 | G4: 0 | H4: 0 | I4: 0 | J4: 0 | M4: File Processed | P4: Sender
A5: 2 | B5: =G5 -> -0.17 | C5: =H5 -> 0.24 | D5: =I5-R$12 -> 69.6 | E5: =J5 -> 100 | G5: -0.17 | H5: 0.24 | I5: 100 | J5: 100 | M5: =Introduction!C15 -> FORGE directional surveys.xls
A6: 3 | B6: =G6 -> -0.56 | C6: =H6 -> 0.73 | D6: =I6-R$12 -> 169.6 | E6: =J6 -> 200 | G6: -0.56 | H6: 0.73 | I6: 200 | J6: 200 | M6: Clay Jones 3/2/22 FORGE wellhead flanges wrt GL.docx
A7: 4 | B7: =G7 -> -1.05 | C7: =H7 -> 1.22 | D7: =I7-R$12 -> 269.6 | E7: =J7 -> 300 | G7: -1.05 | H7: 1.22 | I7: 300 | J7: 300 | M7: Easting (X) [m] | N7: Northing (Y ) [m] | O7: Latitude | P7: Longitude | Q7: Elevation [m] | R7: Kelly Bushing [m] | S7: Flange
A8: 5 | B8: =G8 -> -1.47 | C8: =H8 -> 1.6 | D8: =I8-R$12 -> 369.59 | E8: =J8 -> 400 | G8: -1.47 | H8: 1.6 | I8: 399.99 | J8: 400 | L8: Well's actual location | M8: =Introduction!C39 -> 334641.19 | N8: =Introduction!D39 -> 4263443.7 | O8: =Introduction!E39 -> 38.504021 | P8: =Introduction!F39 -> -112.89639 | Q8: =Introduction!G39 -> 1650.0249 | R8: =R12*0.3048 -> 9.26592
A9: 6 | B9: =G9 -> -1.54 | C9: =H9 -> 1.51 | D9: =I9-R$12 -> 469.59 | E9: =J9 -> 500 | G9: -1.54 | H9: 1.51 | I9: 499.99 | J9: 500 | L9: Wellhead wrt 16A | M9: =M8-Introduction!C20 -> 0 | N9: =N8-Introduction!D20 -> 0 | Q9: =Q8-Introduction!H20 -> 0
A10: 7 | B10: =G10 -> -1.34 | C10: =H10 -> 0.81 | D10: =I10-R$12 -> 569.59 | E10: =J10 -> 600 | G10: -1.34 | H10: 0.81 | I10: 599.99 | J10: 600
A11: 8 | B11: =G11 -> -1.28 | C11: =H11 -> -0.13 | D11: =I11-R$12 -> 669.59 | E11: =J11 -> 700 | G11: -1.28 | H11: -0.13 | I11: 699.99 | J11: 700 | M11: Easting (X) [usft] | N11: Northing (Y ) [usft] | O11: Latitude | P11: Longitude | Q11: Elevation [usft] | R11: Kelly Bushing [ft]
A12: 9 | B12: =G12 -> -1.48 | C12: =H12 -> -1.21 | D12: =I12-R$12 -> 769.58 | E12: =J12 -> 800 | G12: -1.48 | H12: -1.21 | I12: 799.98 | J12: 800 | L12: Well's actual location | M12: =M8/0.3048 -> 1097904.2 | N12: =N8/0.3048 -> 13987676 | O12: =O8 -> 38.504021 | P12: =P8 -> -112.89639 | Q12: =Q8/0.3048 -> 5413.4675 | R12: =Introduction!L20 -> 30.4 | S12: 81.5"
A13: 10 | B13: =G13 -> -1.77 | C13: =H13 -> -2.79 | D13: =I13-R$12 -> 869.57 | E13: =J13 -> 900 | G13: -1.77 | H13: -2.79 | I13: 899.97 | J13: 900 | L13: Wellhead wrt 16A | M13: =M9/0.3048 -> 0 | N13: =N9/0.3048 -> 0 | Q13: =Q9/0.3048 -> 0
A14: 11 | B14: =G14 -> -2.09 | C14: =H14 -> -5.08 | D14: =I14-R$12 -> 969.54 | E14: =J14 -> 1000 | G14: -2.09 | H14: -5.08 | I14: 999.94 | J14: 1000
A15: 12 | B15: =G15 -> -2.37 | C15: =H15 -> -8.04 | D15: =I15-R$12 -> 1069.5 | E15: =J15 -> 1100 | G15: -2.37 | H15: -8.04 | I15: 1099.9 | J15: 1100
A16: 13 | B16: =G16 -> -2.36 | C16: =H16 -> -11.47 | D16: =I16-R$12 -> 1169.44 | E16: =J16 -> 1200 | G16: -2.36 | H16: -11.47 | I16: 1199.84 | J16: 1200 | L16: Survey depth reference is KB
A17: 14 | B17: =G17 -> -2.03 | C17: =H17 -> -14.73 | D17: =I17-R$12 -> 1269.38 | E17: =J17 -> 1300 | G17: -2.03 | H17: -14.73 | I17: 1299.78 | J17: 1300 | L17: Our reference is GL at 16A so TVD-KB
A18: 15 | B18: =G18 -> -1.69 | C18: =H18 -> -17.24 | D18: =I18-R$12 -> 1369.35 | E18: =J18 -> 1400 | G18: -1.69 | H18: -17.24 | I18: 1399.75 | J18: 1400
A19: 16 | B19: =G19 -> -1.19 | C19: =H19 -> -18.76 | D19: =I19-R$12 -> 1469.34 | E19: =J19 -> 1500 | G19: -1.19 | H19: -18.76 | I19: 1499.74 | J19: 1500 | L19: Trajectory depth reference | N19: KB | O19: =R12 -> 30.4 | P19: ft above GL
A20: 17 | B20: =G20 -> -0.29 | C20: =H20 -> -19.6 | D20: =I20-R$12 -> 1569.33 | E20: =J20 -> 1600 | G20: -0.29 | H20: -19.6 | I20: 1599.73 | J20: 1600
A21: 18 | B21: =G21 -> 0.88 | C21: =H21 -> -20.27 | D21: =I21-R$12 -> 1669.32 | E21: =J21 -> 1700 | G21: 0.88 | H21: -20.27 | I21: 1699.72 | J21: 1700
A22: 19 | B22: =G22 -> 2.29 | C22: =H22 -> -20.58 | D22: =I22-R$12 -> 1769.31 | E22: =J22 -> 1800 | G22: 2.29 | H22: -20.58 | I22: 1799.71 | J22: 1800
A23: 20 | B23: =G23 -> 3.73 | C23: =H23 -> -20.08 | D23: =I23-R$12 -> 1869.3 | E23: =J23 -> 1900 | G23: 3.73 | H23: -20.08 | I23: 1899.7 | J23: 1900
A24: 21 | B24: =G24 -> 4.42 | C24: =H24 -> -18.66 | D24: =I24-R$12 -> 1969.28 | E24: =J24 -> 2000 | G24: 4.42 | H24: -18.66 | I24: 1999.68 | J24: 2000
A25: 22 | B25: =G25 -> 3.71 | C25: =H25 -> -17.17 | D25: =I25-R$12 -> 2069.27 | E25: =J25 -> 2100 | G25: 3.71 | H25: -17.17 | I25: 2099.67 | J25: 2100
A26: 23 | B26: =G26 -> 2.2 | C26: =H26 -> -16.68 | D26: =I26-R$12 -> 2169.26 | E26: =J26 -> 2200 | G26: 2.2 | H26: -16.68 | I26: 2199.66 | J26: 2200
A27: 24 | B27: =G27 -> 1.13 | C27: =H27 -> -17.25 | D27: =I27-R$12 -> 2269.25 | E27: =J27 -> 2300 | G27: 1.13 | H27: -17.25 | I27: 2299.65 | J27: 2300
A28: 25 | B28: =G28 -> 1.25 | C28: =H28 -> -18.14 | D28: =I28-R$12 -> 2369.24 | E28: =J28 -> 2400 | G28: 1.25 | H28: -18.14 | I28: 2399.64 | J28: 2400
A29: 26 | B29: =G29 -> 2.2 | C29: =H29 -> -18.36 | D29: =I29-R$12 -> 2469.24 | E29: =J29 -> 2500 | G29: 2.2 | H29: -18.36 | I29: 2499.64 | J29: 2500
A30: 27 | B30: =G30 -> 2.93 | C30: =H30 -> -17.41 | D30: =I30-R$12 -> 2569.23 | E30: =J30 -> 2600 | G30: 2.93 | H30: -17.41 | I30: 2599.63 | J30: 2600
A31: 28 | B31: =G31 -> 2.56 | C31: =H31 -> -15.84 | D31: =I31-R$12 -> 2669.22 | E31: =J31 -> 2700 | G31: 2.56 | H31: -15.84 | I31: 2699.62 | J31: 2700
... A114: 111 | B114: =G114 -> 3906.97 | C114: =H114 -> -1042.9 | D114: =I114-R$12 -> 8518.85 | E114: =J114 -> 10955 | G114: 3906.97 | H114: -1042.9 | I114: 8549.25 | J114: 10955
A115: 112 | B115: 3936.17 | C115: -1048.304 | D115: =I115-R$12 -> 8528.6 | E115: =J115 -> 10987 | I115: 8559 | J115: 10987
B117: Point 112 by linear interpolation - BD

Sheet Trajectory58-32
F1: DirectionalSurveyRpt_171027103004.pdf
B2: X | C2: Y | D2: Z TVD | G2: E-W (ft) | H2: N-S (ft) | I2: TVD (ft)
A3: =F3 -> 1 | B3: =G3+L$14 -> 2656.8241 | C3: =H3+M$14 -> -1331.3222 | D3: =I3-P$14 -> -114.00098 | F3: 1 | G3: 0 | H3: 0 | I3: 0
A4: =F4 -> 2 | B4: =G4+L$14 -> 2657.1241 | C4: =H4+M$14 -> -1330.6222 | D4: =I4-P$14 -> 163.99902 | F4: 2 | G4: 0.3 | H4: 0.7 | I4: 278
A5: =F5 -> 3 | B5: =G5+L$14 -> 2657.0241 | C5: =H5+M$14 -> -1330.6222 | D5: =I5-P$14 -> 467.99902 | F5: 3 | G5: 0.2 | H5: 0.7 | I5: 582 | L5: File Processed | O5: Sender
A6: =F6 -> 4 | B6: =G6+L$14 -> 2656.7241 | C6: =H6+M$14 -> -1330.3222 | D6: =I6-P$14 -> 753.99902 | F6: 4 | G6: -0.1 | H6: 1 | I6: 868 | L6: =Introduction!E15 -> DirectionalSurveyRpt_171027103004.pdf | O6: =Introduction!F17 -> 0
A7: =F7 -> 5 | B7: =G7+L$14 -> 2656.0241 | C7: =H7+M$14 -> -1326.5222 | D7: =I7-P$14 -> 1070.999 | F7: 5 | G7: -0.8 | H7: 4.8 | I7: 1185 | L7: Clay Jones 3/2/22 FORGE wellhead flanges wrt GL.docx
A8: =F8 -> 6 | B8: =G8+L$14 -> 2654.9241 | C8: =H8+M$14 -> -1321.6222 | D8: =I8-P$14 -> 1356.899 | F8: 6 | G8: -1.9 | H8: 9.7 | I8: 1470.9 | L8: Easting (X) [m] | M8: Northing (Y ) [m] | N8: Latitude | O8: Longitude | P8: Elevation [m] | Q8: Kelly Bushing [m] | R8: Flange
A9: =F9 -> 7 | B9: =G9+L$14 -> 2652.7241 | C9: =H9+M$14 -> -1315.7222 | D9: =I9-P$14 -> 1674.899 | F9: 7 | G9: -4.1 | H9: 15.6 | I9: 1788.9 | K9: Well's actual location | L9: =Introduction!C49 -> 335450.99 | M9: =Introduction!D49 -> 4263037.9 | N9: =Introduction!E49 -> 38.500516 | O9: =Introduction!F49 -> -112.88701 | P9: =Introduction!G49 -> 1684.7724 | Q9: =Q13*0.3048 -> 6.5532
A10: =F10 -> 8 | B10: =G10+L$14 -> 2653.3241 | C10: =H10+M$14 -> -1306.9222 | D10: =I10-P$14 -> 2023.699 | F10: 8 | G10: -3.5 | H10: 24.4 | I10: 2137.7 | K10: Wellhead wrt 16A | L10: =L9-Introduction!C20 -> 809.8 | M10: =M9-Introduction!D20 -> -405.787 | P10: =P9-Introduction!H20 -> 34.7475
A11: =F11 -> 9 | B11: =G11+L$14 -> 2657.8241 | C11: =H11+M$14 -> -1302.6222 | D11: =I11-P$14 -> 2283.699 | F11: 9 | G11: 1 | H11: 28.7 | I11: 2397.7
A12: =F12 -> 10 | B12: =G12+L$14 -> 2662.0241 | C12: =H12+M$14 -> -1300.0222 | D12: =I12-P$14 -> 2653.599 | F12: 10 | G12: 5.2 | H12: 31.3 | I12: 2767.6 | L12: Easting (X) [usft] | M12: Northing (Y ) [usft] | N12: Latitude | O12: Longitude | P12: Elevation [usft] | Q12: Kelly Bushing [ft]
A13: =F13 -> 11 | B13: =G13+L$14 -> 2659.8241 | C13: =H13+M$14 -> -1295.9222 | D13: =I13-P$14 -> 2970.599 | F13: 11 | G13: 3 | H13: 35.4 | I13: 3084.6 | K13: Well's actual location | L13: =L9/0.3048 -> 1100561 | M13: =M9/0.3048 -> 13986345 | N13: =N9 -> 38.500516 | O13: =O9 -> -112.88701 | P13: =P9/0.3048 -> 5527.4685 | Q13: =Introduction!L17 -> 21.5 | R13: 57"
A14: =F14 -> 12 | B14: =G14+L$14 -> 2660.1241 | C14: =H14+M$14 -> -1295.5222 | D14: =I14-P$14 -> 3265.599 | F14: 12 | G14: 3.3 | H14: 35.8 | I14: 3379.6 | K14: Wellhead wrt 16A | L14: =L10/0.3048 -> 2656.8241 | M14: =M10/0.3048 -> -1331.3222 | P14: =P10/0.3048 -> 114.00098
A15: =F15 -> 13 | B15: =G15+L$14 -> 2659.8241 | C15: =H15+M$14 -> -1300.9222 | D15: =I15-P$14 -> 3582.499 | F15: 13 | G15: 3 | H15: 30.4 | I15: 3696.5
A16: =F16 -> 14 | B16: =G16+L$14 -> 2648.3241 | C16: =H16+M$14 -> -1306.7222 | D16: =I16-P$14 -> 3861.199 | F16: 14 | G16: -8.5 | H16: 24.6 | I16: 3975.2 | K16: The survey report does not specify the reference for MD
A17: =F17 -> 15 | B17: =G17+L$14 -> 2621.3241 | C17: =H17+M$14 -> -1313.9222 | D17: =I17-P$14 -> 4176.899 | F17: 15 | G17: -35.5 | H17: 17.4 | I17: 4290.9 | K17: Revised Z TVD to be Survey - Elevation
A18: =F18 -> 16 | B18: =G18+L$14 -> 2591.0241 | C18: =H18+M$14 -> -1322.1222 | D18: =I18-P$14 -> 4451.099 | F18: 16 | G18: -65.8 | H18: 9.2 | I18: 4565.1
A19: =F19 -> 17 | B19: =G19+L$14 -> 2586.8241 | C19: =H19+M$14 -> -1322.6222 | D19: =I19-P$14 -> 4484.899 | F19: 17 | G19: -70 | H19: 8.7 | I19: 4598.9 | K19: Trajectory depth reference | M19: 0 | N19: ft | O19: above GL
A20: =F20 -> 18 | B20: =G20+L$14 -> 2578.8241 | C20: =H20+M$14 -> -1322.0222 | D20: =I20-P$14 -> 4548.299 | F20: 18 | G20: -78 | H20: 9.3 | I20: 4662.3
A21: =F21 -> 19 | B21: =G21+L$14 -> 2570.1241 | C21: =H21+M$14 -> -1321.4222 | D21: =I21-P$14 -> 4619.799 | F21: 19 | G21: -86.7 | H21: 9.9 | I21: 4733.8
A22: =F22 -> 20 | B22: =G22+L$14 -> 2566.3241 | C22: =H22+M$14 -> -1321.3222 | D22: =I22-P$14 -> 4651.599 | F22: 20 | G22: -90.5 | H22: 10 | I22: 4765.6
A23: =F23 -> 21 | B23: =G23+L$14 -> 2562.3241 | C23: =H23+M$14 -> -1321.2222 | D23: =I23-P$14 -> 4683.299 | F23: 21 | G23: -94.5 | H23: 10.1 | I23: 4797.3
A24: =F24 -> 22 | B24: =G24+L$14 -> 2558.6241 | C24: =H24+M$14 -> -1321.0222 | D24: =I24-P$14 -> 4713.099 | F24: 22 | G24: -98.2 | H24: 10.3 | I24: 4827.1
A25: =F25 -> 23 | B25: =G25+L$14 -> 2554.7241 | C25: =H25+M$14 -> -1320.6222 | D25: =I25-P$14 -> 4744.899 | F25: 23 | G25: -102.1 | H25: 10.7 | I25: 4858.9
A26: =F26 -> 24 | B26: =G26+L$14 -> 2551.3241 | C26: =H26+M$14 -> -1320.2222 | D26: =I26-P$14 -> 4776.699 | F26: 24 | G26: -105.5 | H26: 11.1 | I26: 4890.7
A27: =F27 -> 25 | B27: =G27+L$14 -> 2548.3241 | C27: =H27+M$14 -> -1319.8222 | D27: =I27-P$14 -> 4807.499 | F27: 25 | G27: -108.5 | H27: 11.5 | I27: 4921.5
A28: =F28 -> 26 | B28: =G28+L$14 -> 2545.6241 | C28: =H28+M$14 -> -1319.5222 | D28: =I28-P$14 -> 4839.399 | F28: 26 | G28: -111.2 | H28: 11.8 | I28: 4953.4
A29: =F29 -> 27 | B29: =G29+L$14 -> 2543.2241 | C29: =H29+M$14 -> -1319.5222 | D29: =I29-P$14 -> 4871.299 | F29: 27 | G29: -113.6 | H29: 11.8 | I29: 4985.3
A30: =F30 -> 28 | B30: =G30+L$14 -> 2541.3241 | C30: =H30+M$14 -> -1319.7222 | D30: =I30-P$14 -> 4903.299 | F30: 28 | G30: -115.5 | H30: 11.6 | I30: 5017.3
A31: =F31 -> 29 | B31: =G31+L$14 -> 2540.0241 | C31: =H31+M$14 -> -1320.1222 | D31: =I31-P$14 -> 4934.199 | F31: 29 | G31: -116.8 | H31: 11.2 | I31: 5048.2
... A61: =F61 -> 59 | B61: =G61+L$14 -> 2493.5241 | C61: =H61+M$14 -> -1295.7222 | D61: =I61-P$14 -> 7234.899 | F61: 59 | G61: -163.3 | H61: 35.6 | I61: 7348.9

Sheet VSP
A1: Vibe points referred to 16A wellhead
B2: X(ft) | C2: Y(ft) | D2: Z(ft) | E2: true_elevation(ft)
A3: 1 | B3: 8519.4949 | C3: -3191.0511 | D3: ='Trajectory16A-32'!Q$12-E3 -> -504.61476 | E3: 5918.0823
A4: 2 | B4: 8519.4949 | C4: -3191.0511 | D4: ='Trajectory16A-32'!Q$12-E4 -> -504.61476 | E4: 5918.0823
A5: 3 | B5: 8519.4949 | C5: -3191.0511 | D5: ='Trajectory16A-32'!Q$12-E5 -> -504.61476 | E5: 5918.0823
A6: 4 | B6: 8450.5684 | C6: -3117.5333 | D6: ='Trajectory16A-32'!Q$12-E6 -> -484.21764 | E6: 5897.6852
A7: 5 | B7: 8450.5684 | C7: -3117.5333 | D7: ='Trajectory16A-32'!Q$12-E7 -> -484.21764 | E7: 5897.6852
A8: 6 | B8: 8450.5684 | C8: -3117.5333 | D8: ='Trajectory16A-32'!Q$12-E8 -> -484.21764 | E8: 5897.6852
A9: 7 | B9: 8389.8018 | C9: -3036.896 | D9: ='Trajectory16A-32'!Q$12-E9 -> -477.80975 | E9: 5891.2773
A10: 8 | B10: 8389.8018 | C10: -3036.896 | D10: ='Trajectory16A-32'!Q$12-E10 -> -477.80975 | E10: 5891.2773
A11: 9 | B11: 8389.8018 | C11: -3036.896 | D11: ='Trajectory16A-32'!Q$12-E11 -> -477.80975 | E11: 5891.2773
A12: 10 | B12: 8325.2051 | C12: -2961.6445 | D12: ='Trajectory16A-32'!Q$12-E12 -> -472.33741 | E12: 5885.8049
A13: 11 | B13: 8325.2051 | C13: -2961.6445 | D13: ='Trajectory16A-32'!Q$12-E13 -> -472.33741 | E13: 5885.8049
A14: 12 | B14: 8325.2051 | C14: -2961.6445 | D14: ='Trajectory16A-32'!Q$12-E14 -> -472.33741 | E14: 5885.8049
... A305: 303 | B305: -423.88086 | C305: 615.40663 | D305: ='Trajectory16A-32'!Q$12-E305 -> 25.592134 | E305: 5387.8754
